<?xml version = "1.0" ?>
<robot name = "dupe_arm">

    <link name = "link1_1">
        <visual>
            <origin xyz = "0.194096 0.117658 -0.012500" rpy = "0 0 0"/>
            <geometry>
                <mesh filename = "package://trial_links/meshes/link1_1.stl" scale = "0.01 0.01 0.01"/>
            </geometry>
        </visual>
        <collision>
            <origin xyz = "0.194096 0.117658 -0.012500" rpy = "0 0 0"/>
            <geometry>
                <mesh filename = "package://trial_links/meshes/link1_1.stl" scale = "0.01 0.01 0.01"/>
            </geometry>
        </collision>
        <inertial>
            <origin xyz = "0.194096 0.117658 -0.012500" rpy = "0 0 0"/>
            <mass value = "9.697442"/>
            <inertia ixx = "0.002042" ixy = "-0.003134" ixz = "0.000235" iyy = "0.005022" iyz = "0.000143" izz = "0.006993"/>
        </inertial>
    </link>
    
    <link name = "link2_1">
        <visual>
            <origin xyz = "0.492115 0.282493 -0.012500" rpy = "0 0 0"/>
            <geometry>
                <mesh filename = "package://trial_links/meshes/link2_1.stl" scale = "0.01 0.01 0.01"/>
            </geometry>
        </visual>
        <collision>
            <origin xyz = "0.492115 0.282493 -0.012500" rpy = "0 0 0"/>
            <geometry>
                <mesh filename = "package://trial_links/meshes/link2_1.stl" scale = "0.01 0.01 0.01"/>
            </geometry>
        </collision>
        <inertial>
            <origin xyz = "0.492115 0.282493 -0.012500" rpy = "0 0 0"/>
            <mass value = "4.398692"/>
            <inertia ixx = "0.003547" ixy = "-0.006159" ixz = "0.000271" iyy = "0.010843" iyz = "0.000155" izz = "0.014358"/>
        </inertial>
    </link>
    
    <link name = "link3_1">
        <visual>
            <origin xyz = "0.728676 0.196274 -0.012500" rpy = "0 0 0"/>
            <geometry>
                <mesh filename = "package://trial_links/meshes/link3_1.stl" scale = "0.01 0.01 0.01"/>
            </geometry>
        </visual>
        <collision>
            <origin xyz = "0.728676 0.196274 -0.012500" rpy = "0 0 0"/>
            <geometry>
                <mesh filename = "package://trial_links/meshes/link3_1.stl" scale = "0.01 0.01 0.01"/>
            </geometry>
        </collision>
        <inertial>
            <origin xyz = "0.728676 0.196274 -0.012500" rpy = "0 0 0"/>
            <mass value = "7.203721"/>
            <inertia ixx = "0.003145" ixy = "-0.009911" ixz = "0.000656" iyy = "0.038757" iyz = "0.000177" izz = "0.041850"/>
        </inertial>
    </link>
    
    <link name = "base_plate_1">
        <visual>
            <origin xyz = "-0.043862 0.004869 -0.012500" rpy = "0 0 0"/>
            <geometry>
                <mesh filename = "package://trial_links/meshes/base_plate_1.stl" scale = "0.01 0.01 0.01"/>
            </geometry>
        </visual>
        <collision>
            <origin xyz = "-0.043862 0.004869 -0.012500" rpy = "0 0 0"/>
            <geometry>
                <mesh filename = "package://trial_links/meshes/base_plate_1.stl" scale = "0.01 0.01 0.01"/>
            </geometry>
        </collision>
        <inertial>
            <origin xyz = "-0.043862 0.004869 -0.012500" rpy = "0 0 0"/>
            <mass value = "4.102668"/>
            <inertia ixx = "0.000292" ixy = "0.000026" ixz = "-0.000022" iyy = "0.000494" iyz = "0.000002" izz = "0.000288"/>
        </inertial>
    </link>
    
    <link name = "base_link">
        <visual>
            <origin xyz = "-0.025000 -0.035000 -0.012500" rpy = "0 0 0"/>
            <geometry>
                <mesh filename = "package://trial_links/meshes/base_link.stl" scale = "0.01 0.01 0.01"/>
            </geometry>
        </visual>
        <collision>
            <origin xyz = "-0.025000 -0.035000 -0.012500" rpy = "0 0 0"/>
            <geometry>
                <mesh filename = "package://trial_links/meshes/base_link.stl" scale = "0.01 0.01 0.01"/>
            </geometry>
        </collision>
        <inertial>
            <origin xyz = "-0.025000 -0.035000 -0.012500" rpy = "0 0 0"/>
            <mass value = "15.307500"/>
            <inertia ixx = "0.001564" ixy = "-0.000134" ixz = "-0.000048" iyy = "0.002615" iyz = "-0.000067" izz = "0.001436"/>
        </inertial>
    </link>
    
    <joint name = "Revolute 4" type = "continuous">
        <origin xyz = "-0.002500 -0.020000 0.012500" rpy = "0 0 0"/>
        <parent link = "base_plate_1"/>
        <child link = "link1_1"/>
        <axis xyz = "0.000000 0.000000 1.000000"/>
    </joint>
    
    <joint name = "Revolute 5" type = "continuous">
        <origin xyz = "0.390693 0.255317 -0.012500" rpy = "0 0 0"/>
        <parent link = "link1_1"/>
        <child link = "link2_1"/>
        <axis xyz = "-0.000000 0.000000 1.000000"/>
    </joint>
    
    <joint name = "Revolute 6" type = "continuous">
        <origin xyz = "0.593537 0.309669 -0.012500" rpy = "0 0 0"/>
        <parent link = "link2_1"/>
        <child link = "link3_1"/>
        <axis xyz = "-0.000000 0.000000 1.000000"/>
    </joint>
    
    <joint name = "Revolute 7" type = "continuous">
        <origin xyz = "-0.025000 -0.020000 -0.012500" rpy = "0 0 0"/>
        <parent link = "base_link"/>
        <child link = "base_plate_1"/>
        <axis xyz = "0.000000 -1.000000 0.000000"/>
    </joint>
    
</robot>
